<?xml version="1.0"?>
<!--
	Space Robotics Challenge (2)
	NASA-JSC
	Copyright (c) 2020, All Rights Reserved
	Unauthorized distribution strictly prohibited
-->
<robot xmlns:xacro="http://www.ros.org/wiki/xacro">
  <xacro:macro name="small_rover_camera_sensor" params="rover_name">

    <xacro:property name="camera_size_x" value="0.10"/> <!-- meters-->
    <xacro:property name="camera_size_y" value="0.30"/> <!-- meters-->
    <xacro:property name="camera_size_z" value="0.10"/> <!-- meters--> 
    <xacro:property name="camera_mass"   value="2.0"/>  <!-- kg -->

    <xacro:macro name="sensor_bar_yaw_joint_origin">
      <origin xyz="0.39 0.38 0.44" rpy="0 0 0"/>
    </xacro:macro>
    <xacro:macro name="sensor_bar_pitch_joint_origin">
      <origin xyz="0.0 0.0 0.02" rpy="0 0 0"/>
    </xacro:macro>

  <!-- Empty link to give the sensor bar a yaw DoF
       (motor plugin does not control multi-dof single joints) -->
    <link name="${rover_name}_sensor_bar_yaw_motor">
      <collision>
          <geometry>
            <cylinder radius="0.02" length="0.02"/>
          </geometry>
      </collision>
      <visual>
          <geometry>
            <cylinder radius="0.02" length="0.02"/>
          </geometry>
      </visual>

      <inertial>
        <mass value="0.2"/>
        <xacro:cylinder_inertia
          m="0.2"
          r="0.02"
          h="0.02"/>
      </inertial>
    </link>

    <joint name="sensor_bar_yaw_joint" type="revolute">
      <xacro:sensor_bar_yaw_joint_origin/>
      <parent link="${rover_name}_small_chassis"/>
      <child  link="${rover_name}_sensor_bar_yaw_motor"/>
      <axis   xyz="0 0 1"/>
      <limit
              upper    = "${pi}" 
              lower    = "-${pi}" 
              effort   = "10" 
              velocity = "0.01"/>
      <!-- Some joint damping is necessary for this joint, as it's a powerful -->
      <!-- motor and a light link. Without this, the PID controller must be  -->
      <!-- perfectly tuned to prevent oscillations -->
      <dynamics
            damping  = "10"
            friction = "1"/>
    </joint>

    <!-- The Sensor Bar, stereo-cameras, Lidar and spotlight live here -->
    <link name="${rover_name}_sensor_bar">

      <collision>
        <origin xyz="0 0.07 0.05" rpy="0 0 0"/>
        <!-- <xacro:sensor_bar_pitch_joint_origin/> -->
        <geometry>
          <box size="${camera_size_x} ${camera_size_y} ${camera_size_z}"/>
        </geometry>
      </collision>

      <visual>
        <origin xyz="0.5 -0.335 -0.52" rpy="0 0 ${pi}"/>
        <geometry>
            <mesh
                filename = "package://srcp2_models_final/meshes/rovers/small_basic/sensor_bar.dae"
                scale    = "0.4 0.4 0.4"/>
        </geometry>
      </visual>

      <inertial>
        <origin xyz="0 0.07 0.05" rpy="0 0 0"/>
        <!-- <xacro:sensor_bar pitch_joint_origin/> -->
        <mass value="${camera_mass}"/>
        <xacro:box_inertia
            m="${camera_mass}"
            x="${camera_size_x}"
            y="${camera_size_y}"
            z="${camera_size_z}"/>
      </inertial>
    </link>

    <joint name="sensor_bar_pitch_joint" type="revolute">
      <xacro:sensor_bar_pitch_joint_origin/>
      <axis   xyz="0 1 0"/>
      <parent link="${rover_name}_sensor_bar_yaw_motor"/>
      <child  link="${rover_name}_sensor_bar"/>
      <limit
              upper    = "${pi/3}" 
              lower    = "-${pi/3}" 
              effort   = "3.0" 
              velocity = "0.25"/>
     <!-- Some joint damping is necessary for this joint, as it's a powerful -->
     <!-- motor and a light link. Without this, the PID controller must be  -->
     <!-- perfectly tuned to prevent oscillations -->
      <dynamics
          damping  = "20"
          friction = "1"/>
    </joint>

    <!-- The Left Camera Optical Link -->
    <link name="${rover_name}_left_camera_optical">
    </link>
    <joint name="left_camera_optical_joint" type="fixed">
        <parent link="${rover_name}_sensor_bar"/>
        <child link="${rover_name}_left_camera_optical"/>
        <origin xyz="0.2 0.2 0.05" rpy="-1.57 0 -1.57"/>
    </joint>


    <!-- The Right Camera Optical Link -->
    <link name="${rover_name}_right_camera_optical">
    </link>
    <joint name="right_camera_optical_joint" type="fixed">
        <parent link="${rover_name}_sensor_bar"/>
        <child link="${rover_name}_right_camera_optical"/>
        <origin xyz="0.2 -0.01 0.05" rpy="-1.57 0 -1.57"/>
    </joint>

  </xacro:macro>


  <!-- The Small Rover Lidar -->
  <xacro:macro name="small_rover_lidar_sensor" params="rover_name">
      <link name="${rover_name}_lidar_link">
      </link>

      <joint name="lidar_joint" type="fixed">
          <parent link="${rover_name}_sensor_bar"/>
          <child link="${rover_name}_lidar_link"/>
          <origin xyz="0.1 0.075 0" rpy="0 0 0"/>
      </joint>

  </xacro:macro>


  <!-- The Small Rover IMU -->
  <xacro:macro name="small_rover_imu_sensor" params="rover_name">
      <xacro:property name="imuSize" value="0.05"/>
      <xacro:property name="imuMass" value="1e-5"/>

      <link name="${rover_name}_imu_link">
          <inertial>
              <origin xyz="0 0 0" rpy="0 ${pi/2} 0" />
              <mass value="${imuMass}" />
              <xacro:cylinder_inertia
              m="${imuMass}" r="${imuSize}" h="${imuSize}" />
          </inertial>
      </link>

      <joint name="imu_joint" type="fixed">
          <parent link="${rover_name}_small_chassis"/>
          <child link="${rover_name}_imu_link"/>
          <origin xyz="0 0 0" rpy="0 0 0"/>
      </joint>

  </xacro:macro>

</robot>